Workbook
Name Activity_Detail_Col: Vocab_NameList!$M$2:$M$26
Name Activity_Detail_Start: Vocab_NameList!$M$2
Name ActivityStype_Col: Vocab_NameList!$M$2:$M$26
Name ActivityStype_Start: Vocab_NameList!$M$2
Name ActivityType_Col: Vocab_NameList!$I$2:$I$26
Name ActivityType_Start: Vocab_NameList!$I$2
Name BlankList: Sheet5!$J$2
Name CommunalSpaces: Sheet5!$E$2:$E$6
Name Help_Col: 'COD-Sites'!$G$2:$G$9998
Name Help_Start: 'COD-Sites'!$G$2
Name ImprovementType: Sheet5!$F$2:$F$6
Name Nei_Col: 'COD-Sites'!$F$2:$F$1883
Name Nei_Start: 'COD-Sites'!$F$2
Name PA_Col: Vocab_NameList!$AJ$2:$AJ$25
Name PA_Start: Vocab_NameList!$AJ$2
Name Partners: Vocab_NameList!$D$2:$D$161
Name Region_Col: Vocab_NameList!$AD$2:$AD$194
Name Region_Start: Vocab_NameList!$AD$2
Name RiskType: Sheet5!$G$2:$G$9
Name Site_Col: 'COD-Sites'!$H$2:$H$1883
Name Site_Start: 'COD-Sites'!$H$2
Name Status: Vocab_NameList!$Q$1:$Q$4

Sheet Read Me

Sheet ActivityReporting (Data Entry)
B1: WHO | D1: WHERE | G1: STATUS | H1: WHAT | O1: CASELOAD/ACHIEVEMENT/BENEFICIARIES
O2: COUNTS/INDIVIDUALS | Q2: AGE SEX DISAGGREGATION (Must be filled for the cells that are not black) | W2: VULNERABILITY (People with Disabilities)
A3: Reporting Month | B3: Organization Name | C3: Program / Coordinating / Donor Organization | D3: Governorate (Select from Dropdown) | E3: Neighborhood (Select from Dropdown) | F3: Site Name (Select from Dropdown, or type name and code if not found) | G3: Activity Status (Select from Dropdown) | H3: Primary Activities (Select From Dropdown) | I3: Sub Activity (Select from Dropdown) | J3: Indicator (Select from Dropdown) | K3: Specification (Select from Dropdown) | L3: Activity Details (Provide additional brief remarks on the activity, if any) | M3: Units (Auto Calculated, Do not modify) | N3: Total Planned/Reached Count | O3: Male | P3: Female | Q3: Boys (<18) | R3: Girls (<18) | S3: Men (18-59) | T3: Women (18-59) | U3: Elderly Male (≥60) | V3: Elderly Female (≥60) | W3: Male-PWD | X3: Female-PWD | Y3: Helper | Z3: Additional Remarks
M4: =IFERROR(INDEX(Vocab_NameList!$O:$O,MATCH($J4, Vocab_NameList!$M:$M, 0)),"") | Y4: =Table2[[#This Row],[Governorate (Select from Dropdown)]]&Table2[[#This Row],[Neighborhood (Select from Dropdown)]]&Table2[[#This Row],[Organization Name]]
M5: =IFERROR(INDEX(Vocab_NameList!$O:$O,MATCH($J5, Vocab_NameList!$M:$M, 0)),"") | Y5: =Table2[[#This Row],[Governorate (Select from Dropdown)]]&Table2[[#This Row],[Neighborhood (Select from Dropdown)]]&Table2[[#This Row],[Organization Name]]
M6: =IFERROR(INDEX(Vocab_NameList!$O:$O,MATCH($J6, Vocab_NameList!$M:$M, 0)),"") | Y6: =Table2[[#This Row],[Governorate (Select from Dropdown)]]&Table2[[#This Row],[Neighborhood (Select from Dropdown)]]&Table2[[#This Row],[Organization Name]]
M7: =IFERROR(INDEX(Vocab_NameList!$O:$O,MATCH($J7, Vocab_NameList!$M:$M, 0)),"") | Y7: =Table2[[#This Row],[Governorate (Select from Dropdown)]]&Table2[[#This Row],[Neighborhood (Select from Dropdown)]]&Table2[[#This Row],[Organization Name]]
M8: =IFERROR(INDEX(Vocab_NameList!$O:$O,MATCH($J8, Vocab_NameList!$M:$M, 0)),"") | Y8: =Table2[[#This Row],[Governorate (Select from Dropdown)]]&Table2[[#This Row],[Neighborhood (Select from Dropdown)]]&Table2[[#This Row],[Organization Name]]
M9: =IFERROR(INDEX(Vocab_NameList!$O:$O,MATCH($J9, Vocab_NameList!$M:$M, 0)),"") | Y9: =Table2[[#This Row],[Governorate (Select from Dropdown)]]&Table2[[#This Row],[Neighborhood (Select from Dropdown)]]&Table2[[#This Row],[Organization Name]]
M10: =IFERROR(INDEX(Vocab_NameList!$O:$O,MATCH($J10, Vocab_NameList!$M:$M, 0)),"") | Y10: =Table2[[#This Row],[Governorate (Select from Dropdown)]]&Table2[[#This Row],[Neighborhood (Select from Dropdown)]]&Table2[[#This Row],[Organization Name]]
M11: =IFERROR(INDEX(Vocab_NameList!$O:$O,MATCH($J11, Vocab_NameList!$M:$M, 0)),"") | Y11: =Table2[[#This Row],[Governorate (Select from Dropdown)]]&Table2[[#This Row],[Neighborhood (Select from Dropdown)]]&Table2[[#This Row],[Organization Name]]
M12: =IFERROR(INDEX(Vocab_NameList!$O:$O,MATCH($J12, Vocab_NameList!$M:$M, 0)),"") | Y12: =Table2[[#This Row],[Governorate (Select from Dropdown)]]&Table2[[#This Row],[Neighborhood (Select from Dropdown)]]&Table2[[#This Row],[Organization Name]]
M13: =IFERROR(INDEX(Vocab_NameList!$O:$O,MATCH($J13, Vocab_NameList!$M:$M, 0)),"") | Y13: =Table2[[#This Row],[Governorate (Select from Dropdown)]]&Table2[[#This Row],[Neighborhood (Select from Dropdown)]]&Table2[[#This Row],[Organization Name]]
M14: =IFERROR(INDEX(Vocab_NameList!$O:$O,MATCH($J14, Vocab_NameList!$M:$M, 0)),"") | Y14: =Table2[[#This Row],[Governorate (Select from Dropdown)]]&Table2[[#This Row],[Neighborhood (Select from Dropdown)]]&Table2[[#This Row],[Organization Name]]
M15: =IFERROR(INDEX(Vocab_NameList!$O:$O,MATCH($J15, Vocab_NameList!$M:$M, 0)),"") | Y15: =Table2[[#This Row],[Governorate (Select from Dropdown)]]&Table2[[#This Row],[Neighborhood (Select from Dropdown)]]&Table2[[#This Row],[Organization Name]]
... M500: =IFERROR(INDEX(Vocab_NameList!$O:$O,MATCH($J500, Vocab_NameList!$M:$M, 0)),"") | Y500: =Table2[[#This Row],[Governorate (Select from Dropdown)]]&Table2[[#This Row],[Neighborhood (Select from Dropdown)]]&Table2[[#This Row],[Organization Name]]

Sheet Activity Index
A1: Primary Activity | B1: Sub Activity | C1: Indicators | D1: Additional options | E1: Activity_Code | F1: Unit | G1: Indicator Purpose
A2: Establishment and strengthening of community representation structures, with two way communication mechanisms in place | B2: Establishment or support provided to community representation structures | C2: People in displacement sites with community representation structures supported by Site Management Agencies | E2: SMC_IND_001 | F2: # of individuals | G2: Flash Appeal 2026
A3: Establishment and strengthening of community representation structures, with two way communication mechanisms in place | B3: Facilitation of Community Led Projects | C3: Community-led projects implemented | E3: SMC_IND_002 | F3: # of CLPs | G3: SMC Coordination
A4: Establishment and strengthening of community representation structures, with two way communication mechanisms in place | B4: Information sharing and feedback mechanisms in place | C4: IEC awareness raising products disseminated | E4: SMC_IND_003 | F4: # of products | G4: SMC Coordination
A5: Establishment and strengthening of community representation structures, with two way communication mechanisms in place | B5: Information sharing and feedback mechanisms in place | C5: Participants in Community Feedback Mechanism information sessions | E5: SMC_IND_004 | F5: # of participants | G5: SMC Coordination
A6: Establishment and strengthening of community representation structures, with two way communication mechanisms in place | B6: Information sharing and feedback mechanisms in place | C6: People in sites reached by IEC and awareness raising materials | E6: SMC_IND_005 | F6: # of people | G6: SMC Coordination
A7: Establishment and strengthening of community representation structures, with two way communication mechanisms in place | B7: Information sharing and feedback mechanisms in place | C7: Sites with Community Feedback Mechanisms in place: Information sessions facilitated, or information materials made available to residents. | E7: SMC_IND_006 | F7: # of sites | G7: SMC Coordination
A8: Support to populations to transition out of sites including support to populations out of sites, community engagement, support for relocation and safe site closures. | B8: Plan and implement site closure and exit strategies | C8: Sites safely closed or decommissioned with land returned to orginal use | E8: SMC_IND_007 | F8: # of sites | G8: SMC Coordination
A9: Provision of site management services including strengthened coordination mechanisms, regular site monitoring, service mapping, and robust referral systems to address gaps and avoid duplication. | B9: Population movement monitoring activities | C9: Population flow counting points are active during high population movement periods | E9: SMC_IND_009 | F9: # of days | G9: SMC Coordination
A10: Provision of site management services including strengthened coordination mechanisms, regular site monitoring, service mapping, and robust referral systems to address gaps and avoid duplication. | B10: Protection mainstreaming | C10: Sites with protection referral pathway in place | E10: SMC_IND_010 | F10: # of sites | G10: SMC Coordination
A11: Provision of site management services including strengthened coordination mechanisms, regular site monitoring, service mapping, and robust referral systems to address gaps and avoid duplication. | B11: Protection mainstreaming | C11: Sites with safety audits conducted | E11: SMC_IND_011 | F11: # of sites | G11: SMC Coordination
A12: Provision of site management services including strengthened coordination mechanisms, regular site monitoring, service mapping, and robust referral systems to address gaps and avoid duplication. | B12: Service coordination supported and improved | C12: Number of service/infrastructure mapping reports generated | E12: SMC_IND_013 | F12: # of reports | G12: SMC Coordination
A13: Provision of site management services including strengthened coordination mechanisms, regular site monitoring, service mapping, and robust referral systems to address gaps and avoid duplication. | B13: Service coordination supported and improved | C13: Number of site-level coordination meetings | E13: SMC_IND_014 | F13: # of meetings | G13: SMC Coordination
A14: Provision of site management services including strengthened coordination mechanisms, regular site monitoring, service mapping, and robust referral systems to address gaps and avoid duplication. | B14: Service coordination supported and improved | C14: People in sites managed or supported by trained Site Management teams | E14: SMC_IND_015 | F14: # of individuals | G14: Flash Appeal 2026
A15: Works to increase safety and improve dignity of site environments, with risk mitigation measures in place to respond to incidents including seasonal impacts. | B15: Site maintenance, risk reduction and improvements | C15: Communal spaces established or improved in sites (including safe spaces, child-friendly spaces, committee spaces, community resource spaces) | D15: Safe spaces, Child-friendly spaces, Committee spaces, Community resource spaces, Other (describe) | E15: SMC_IND_016 | F15: # of spaces | G15: SMC Coordination
A16: Works to increase safety and improve dignity of site environments, with risk mitigation measures in place to respond to incidents including seasonal impacts. | B16: Site maintenance, risk reduction and improvements | C16: Number of individuals trained / supported to conduct site care and maintenance | D16: Fire, Flood, Extreme Heat, Infestation, Landslide, Sanitation, Waster, Other (Describe), Not Applicable | E16: SMC_IND_017 | F16: # of individuals | G16: SMC Coordination
A17: Works to increase safety and improve dignity of site environments, with risk mitigation measures in place to respond to incidents including seasonal impacts. | B17: Site maintenance, risk reduction and improvements | C17: Number of sand/flour bags distributed | D17: Fire, Flood, Extreme Heat, Infestation, Landslide, Sanitation, Waster, Other (Describe), Not Applicable | E17: SMC_IND_018 | F17: # of bags | G17: SMC Coordination
A18: Works to increase safety and improve dignity of site environments, with risk mitigation measures in place to respond to incidents including seasonal impacts. | B18: Site maintenance, risk reduction and improvements | C18: Number of tools distributed for site improvement (count individual tools, not toolkits) | E18: SMC_IND_019 | F18: # of tools | G18: SMC Coordination
A19: Works to increase safety and improve dignity of site environments, with risk mitigation measures in place to respond to incidents including seasonal impacts. | B19: Site maintenance, risk reduction and improvements | C19: People in displacement sites with improvements made in site planning, facilities and/or infrastructure including (construction/repair/cleaning drainage, slope stabilisation, etc.) either directly or through community led projects | D19: Fire, Flood, Extreme Heat, Infestation, Landslide, Sanitation, Waster, Other (Describe), Not Applicable | E19: SMC_IND_020 | F19: # of individuals | G19: Flash Appeal 2026
A20: Works to increase safety and improve dignity of site environments, with risk mitigation measures in place to respond to incidents including seasonal impacts. | B20: Site maintenance, risk reduction and improvements | C20: People in sites hired via Cash for Work for site maintenance/improvement | D20: Fire, Flood, Extreme Heat, Infestation, Landslide, Sanitation, Waster, Other (Describe), Not Applicable | E20: SMC_IND_021 | F20: # of individuals | G20: SMC Coordination
A21: Support to populations to transition out of sites including support to populations out of sites, community engagement, support for relocation and safe site closures. | B21: Support safe transition of site based populations | C21: Individuals supported by Site Management projects facilitating transition through access to services. Including area based site management, hubs, and community resource centres. | E21: SMC_IND_022 | F21: # of individuals | G21: Flash Appeal 2026
A22: Support to populations to transition out of sites including support to populations out of sites, community engagement, support for relocation and safe site closures. | B22: Support safe transition of site based populations | C22: Site Management projects facilitating transition through access to services. Including area based site management, hubs, and community resource centres. | E22: SMC_IND_023 | F22: # of projects | G22: Flash Appeal 2027
A23: Establishment and strengthening of community representation structures, with two way communication mechanisms in place | B23: Training provided to community representation structures | C23: Number of individuals who have recieved training in community representation structures | E23: SMC_IND_024 | F23: # of participants | G23: SMC Coordination
A24: Establishment and strengthening of community representation structures, with two way communication mechanisms in place | B24: Training provided to community representation structures | C24: Trainings provided to community representation structures | E24: SMC_IND_025 | F24: # of trainings | G24: SMC Coordination
A25: Capacity-strengthening for SMA staff and voluntunteers, CBOs, other sectoral agencies and stakeholders | B25: Training provided to SMA, CBO, and other stakeholders | C25: Individuals received training in Site Management, including SMA and CBO staff and volunteers, and other stakeholders. | E25: SMC_IND_026 | F25: # of individuals | G25: Flash Appeal 2026
A26: Support to populations to transition out of sites including support to populations out of sites, community engagement, support for relocation and safe site closures. | B26: Undertake intentions and perceptions surveys | C26: Intentions or perceptions surveys conducted | E26: SMC_IND_027 | F26: # of assessments | G26: SMC Coordination

Sheet Sheet5
A1: Establishment and strengthening of community representation structures, with two way communication mechanisms in place | C1: Establishment or support provided to community representation structures | E1: CommunalSpaces | F1: ImprovementType | G1: RiskType | H1: Indicator Keyword | I1: List Name | J1: BlankList
A2: Support to populations to transition out of sites including support to populations out of sites, community engagement, support for relocation and safe site closures. | C2: Facilitation of Community Led Projects | E2: Safe Spaces | F2: Construction | G2: Fire | H2: Communal spaces established | I2: CommunalSpaces
A3: Provision of site management services including strengthened coordination mechanisms, regular site monitoring, service mapping, and robust referral systems to address gaps and avoid duplication. | C3: Information sharing and feedback mechanisms in place | E3: Child-Friendly Spaces | F3: Repair | G3: Flood | H3: improvements made in site planning | I3: ImprovementType
A4: Works to increase safety and improve dignity of site environments, with risk mitigation measures in place to respond to incidents including seasonal impacts. | C4: Plan and implement site closure and exit strategies | E4: Committee Spaces | F4: Cleaning Drainage | G4: Extreme Heat | H4: Cash for Work for site maintenance | I4: ImprovementType
A5: Capacity-strengthening for SMA staff and voluntunteers, CBOs, other sectoral agencies and stakeholders | C5: Population movement monitoring activities | E5: Community Resource Spaces | F5: Slope Stabilization | G5: Infestation | H5: site care and maintenance | I5: RiskType
C6: Protection mainstreaming | E6: Other (Describe in Column L) | F6: Other | G6: Landslide
C7: Service coordination supported and improved | G7: Sanitation
C8: Site maintenance, risk reduction and improvements | G8: Waster
C9: Support safe transition of site based populations | G9: Other (Describe)
C10: Training provided to community representation structures | G10: Not applicable
C11: Training provided to SMA, CBO, and other stakeholders
C12: Undertake intentions and perceptions surveys

Sheet Vocab_NameList
B1: Partner | D1: Partner | F1: Activity Type | I1: Activity Type | J1: Activity Sub-Type | L1: Activity Type | M1: Activity Sub-Type | N1: Activity_Code | O1: Unit | Q1: Planned | S1: ActivityCode | T1: Concat1 | U1: ActivityCode | V1: Units | X1: Reporting Month | Z1: Governorate | AA1: PCODE_Gove | AC1: PCODE_Gove | AD1: Governorat | AE1: Neighbourh | AF1: PCODE_Neig | AH1: Primary Activities | AJ1: Primary Activities | AK1: ActivityType | AM1: Activity Type | AO1: Activity Type | AP1: Activity Sub-Type | AR1: Activity Type | AS1: Activity Sub Type | AT1: Units | AU1: Activity Code
B2: ACTED | D2: ACTED | F2: Establishment or support provided to community representation structures | I2: Establishment or support provided to community representation structures | J2: People in displacement sites with community representation structures supported by Site Management Agencies | L2: Establishment or support provided to community representation structures | M2: People in displacement sites with community representation structures supported by Site Management Agencies | N2: SMC_IND_001 | O2: # of individuals | Q2: Ongoing | S2: SMC_IND_001 | T2: =L2&M2 -> Establishment or support provided to community representation structuresPeople in displacement sites with community representation structures supported by Site Management Agencies | U2: SMC_IND_001 | V2: # of individuals | X2: January | Z2: Khan Yunis | AA2: 270 | AC2: 265 | AD2: Deir al Balah | AE2: Abu Al-'Ajeen | AF2: 2651138 | AH2: Establishment and strengthening of community representation structures, with two way communication mechanisms in place | AJ2: Establishment and strengthening of community representation structures, with two way communication mechanisms in place | AK2: Establishment or support provided to community representation structures | AM2: Establishment or support provided to community representation structures | AO2: Establishment or support provided to community representation structures | AP2: People in displacement sites with community representation structures supported by Site Management Agencies | AR2: Establishment or support provided to community representation structures | AS2: People in displacement sites with community representation structures supported by Site Management Agencies | AT2: SMC_IND_001 | AU2: # of individuals
B3: BLDA | D3: BLDA | F3: Facilitation of Community Led Projects | I3: Facilitation of Community Led Projects | J3: Community-led projects implemented | L3: Facilitation of Community Led Projects | M3: Community-led projects implemented | N3: SMC_IND_002 | O3: # of CLPs | Q3: Completed | S3: SMC_IND_002 | T3: =L3&M3 -> Facilitation of Community Led ProjectsCommunity-led projects implemented | U3: SMC_IND_002 | V3: # of CLPs | X3: February | Z3: Gaza | AA3: 260 | AC3: 265 | AD3: Deir al Balah | AE3: Abu Hdaf | AF3: 2651143 | AH3: Support to populations to transition out of sites including support to populations out of sites, community engagement, support for relocation and safe site closures. | AJ3: Establishment and strengthening of community representation structures, with two way communication mechanisms in place | AK3: Facilitation of Community Led Projects | AM3: Facilitation of Community Led Projects | AO3: Facilitation of Community Led Projects | AP3: Community-led projects implemented | AR3: Facilitation of Community Led Projects | AS3: Community-led projects implemented | AT3: SMC_IND_002 | AU3: # of CLPs
B4: CESVI | D4: CESVI | F4: Information sharing and feedback mechanisms in place | I4: Information sharing and feedback mechanisms in place | J4: IEC awareness raising products disseminated | L4: Information sharing and feedback mechanisms in place | M4: IEC awareness raising products disseminated | N4: SMC_IND_003 | O4: # of products | Q4: Not Applicable | S4: SMC_IND_003 | T4: =L4&M4 -> Information sharing and feedback mechanisms in placeIEC awareness raising products disseminated | U4: SMC_IND_003 | V4: # of products | X4: March | Z4: Deir Al Balah | AA4: 255 | AC4: 265 | AD4: Deir al Balah | AE4: Abu Mgheiseb | AF4: 2651144 | AH4: Provision of site management services including strengthened coordination mechanisms, regular site monitoring, service mapping, and robust referral systems to address gaps and avoid duplication. | AJ4: Establishment and strengthening of community representation structures, with two way communication mechanisms in place | AK4: Information sharing and feedback mechanisms in place | AM4: Information sharing and feedback mechanisms in place | AO4: Information sharing and feedback mechanisms in place | AP4: IEC awareness raising products disseminated | AR4: Information sharing and feedback mechanisms in place | AS4: IEC awareness raising products disseminated | AT4: SMC_IND_003 | AU4: # of products
B5: DRC | D5: DRC | F5: Plan and implement site closure and exit strategies | I5: Information sharing and feedback mechanisms in place | J5: Participants in Community Feedback Mechanism information sessions | L5: Information sharing and feedback mechanisms in place | M5: Participants in Community Feedback Mechanism information sessions | N5: SMC_IND_004 | O5: # of participants | S5: SMC_IND_004 | T5: =L5&M5 -> Information sharing and feedback mechanisms in placeParticipants in Community Feedback Mechanism information sessions | U5: SMC_IND_004 | V5: # of participants | X5: April | Z5: North Gaza | AA5: 265 | AC5: 265 | AD5: Deir al Balah | AE5: Abu Thaher | AF5: 2651146 | AH5: Works to increase safety and improve dignity of site environments, with risk mitigation measures in place to respond to incidents including seasonal impacts. | AJ5: Establishment and strengthening of community representation structures, with two way communication mechanisms in place | AK5: Information sharing and feedback mechanisms in place | AM5: Plan and implement site closure and exit strategies | AO5: Information sharing and feedback mechanisms in place | AP5: Participants in Community Feedback Mechanism information sessions | AR5: Information sharing and feedback mechanisms in place | AS5: Participants in Community Feedback Mechanism information sessions | AT5: SMC_IND_004 | AU5: # of participants
B6: FADE | D6: FADE | F6: Population movement monitoring activities | I6: Information sharing and feedback mechanisms in place | J6: People in sites reached by IEC and awareness raising materials | L6: Information sharing and feedback mechanisms in place | M6: People in sites reached by IEC and awareness raising materials | N6: SMC_IND_005 | O6: # of people | S6: SMC_IND_005 | T6: =L6&M6 -> Information sharing and feedback mechanisms in placePeople in sites reached by IEC and awareness raising materials | U6: SMC_IND_005 | V6: # of people | X6: May | Z6: Rafah | AA6: 275 | AC6: 265 | AD6: Deir al Balah | AE6: Ad Damitha'a | AF6: 2650886 | AH6: Capacity-strengthening for SMA staff and voluntunteers, CBOs, other sectoral agencies and stakeholders | AJ6: Establishment and strengthening of community representation structures, with two way communication mechanisms in place | AK6: Information sharing and feedback mechanisms in place | AM6: Population movement monitoring activities | AO6: Information sharing and feedback mechanisms in place | AP6: People in sites reached by IEC and awareness raising materials | AR6: Information sharing and feedback mechanisms in place | AS6: People in sites reached by IEC and awareness raising materials | AT6: SMC_IND_005 | AU6: # of people
B7: FAFD | D7: FAFD | F7: Protection mainstreaming | I7: Information sharing and feedback mechanisms in place | J7: Sites with Community Feedback Mechanisms in place: Information sessions facilitated, or information materials made available to residents. | L7: Information sharing and feedback mechanisms in place | M7: Sites with Community Feedback Mechanisms in place: Information sessions facilitated, or information materials made available to residents. | N7: SMC_IND_006 | O7: # of sites | S7: SMC_IND_006 | T7: =L7&M7 -> Information sharing and feedback mechanisms in placeSites with Community Feedback Mechanisms in place: Information sessions facilitated, or information materials made available to residents. | U7: SMC_IND_006 | V7: # of sites | X7: June | AC7: 265 | AD7: Deir al Balah | AE7: Al Amal | AF7: 2650583 | AJ7: Establishment and strengthening of community representation structures, with two way communication mechanisms in place | AK7: Information sharing and feedback mechanisms in place | AM7: Protection mainstreaming | AO7: Information sharing and feedback mechanisms in place | AP7: Sites with Community Feedback Mechanisms in place: Information sessions facilitated, or information materials made available to residents. | AR7: Information sharing and feedback mechanisms in place | AS7: Sites with Community Feedback Mechanisms in place: Information sessions facilitated, or information materials made available to residents. | AT7: SMC_IND_006 | AU7: # of sites
B8: HEKS | D8: HEKS | F8: Service coordination supported and improved | I8: Plan and implement site closure and exit strategies | J8: Sites safely closed or decommissioned with land returned to orginal use | L8: Plan and implement site closure and exit strategies | M8: Sites safely closed or decommissioned with land returned to orginal use | N8: SMC_IND_007 | O8: # of sites | S8: SMC_IND_007 | T8: =L8&M8 -> Plan and implement site closure and exit strategiesSites safely closed or decommissioned with land returned to orginal use | U8: SMC_IND_007 | V8: # of sites | X8: July | AC8: 265 | AD8: Deir al Balah | AE8: Al Awda | AF8: 2650579 | AJ8: Support to populations to transition out of sites including support to populations out of sites, community engagement, support for relocation and safe site closures. | AK8: Plan and implement site closure and exit strategies | AM8: Service coordination supported and improved | AO8: Plan and implement site closure and exit strategies | AP8: Sites safely closed or decommissioned with land returned to orginal use | AR8: Plan and implement site closure and exit strategies | AS8: Sites safely closed or decommissioned with land returned to orginal use | AT8: SMC_IND_007 | AU8: # of sites
B9: IOM | D9: IOM | F9: Site maintenance, risk reduction and improvements | I9: Population movement monitoring activities | J9: Population flow counting points are active during high population movement periods | L9: Population movement monitoring activities | M9: Population flow counting points are active during high population movement periods | N9: SMC_IND_009 | O9: # of days | S9: SMC_IND_009 | T9: =L9&M9 -> Population movement monitoring activitiesPopulation flow counting points are active during high population movement periods | U9: SMC_IND_009 | V9: # of days | X9: August | AC9: 265 | AD9: Deir al Balah | AE9: Al Balad | AF9: 2651094 | AJ9: Provision of site management services including strengthened coordination mechanisms, regular site monitoring, service mapping, and robust referral systems to address gaps and avoid duplication. | AK9: Population movement monitoring activities | AM9: Site maintenance, risk reduction and improvements | AO9: Population movement monitoring activities | AP9: Number of individuals in sites where monitoring has been conducted with updated demographic information and needs shared within the response coordination structure | AR9: Population movement monitoring activities | AS9: Number of individuals in sites where monitoring has been conducted with updated demographic information and needs shared within the response coordination structure | AT9: SMC_IND_008 | AU9: # of individuals
B10: MAAN | D10: MAAN | F10: Support safe transition of site based populations | I10: Protection mainstreaming | J10: Sites with protection referral pathway in place | L10: Protection mainstreaming | M10: Sites with protection referral pathway in place | N10: SMC_IND_010 | O10: # of sites | S10: SMC_IND_010 | T10: =L10&M10 -> Protection mainstreamingSites with protection referral pathway in place | U10: SMC_IND_010 | V10: # of sites | X10: September | AC10: 265 | AD10: Deir al Balah | AE10: Al Basateen | AF10: 2650888 | AJ10: Provision of site management services including strengthened coordination mechanisms, regular site monitoring, service mapping, and robust referral systems to address gaps and avoid duplication. | AK10: Population movement monitoring activities | AM10: Support safe transition of site based populations | AO10: Population movement monitoring activities | AP10: Population flow counting points are active during high population movement periods | AR10: Population movement monitoring activities | AS10: Population flow counting points are active during high population movement periods | AT10: SMC_IND_009 | AU10: # of days
B11: NRC | D11: NRC | F11: Training provided to community representation structures | I11: Protection mainstreaming | J11: Sites with safety audits conducted | L11: Protection mainstreaming | M11: Sites with safety audits conducted | N11: SMC_IND_011 | O11: # of sites | S11: SMC_IND_011 | T11: =L11&M11 -> Protection mainstreamingSites with safety audits conducted | U11: SMC_IND_011 | V11: # of sites | X11: October | AC11: 265 | AD11: Deir al Balah | AE11: Al Bassa | AF11: 2651091 | AJ11: Provision of site management services including strengthened coordination mechanisms, regular site monitoring, service mapping, and robust referral systems to address gaps and avoid duplication. | AK11: Protection mainstreaming | AM11: Training provided to community representation structures | AO11: Protection mainstreaming | AP11: Sites with protection referral pathway in place | AR11: Protection mainstreaming | AS11: Sites with protection referral pathway in place | AT11: SMC_IND_010 | AU11: # of sites
B12: PARC | D12: PARC | F12: Training provided to SMA, CBO, and other stakeholders | I12: Service coordination supported and improved | J12: Number of service/infrastructure mapping reports generated | L12: Service coordination supported and improved | M12: Number of service/infrastructure mapping reports generated | N12: SMC_IND_013 | O12: # of reports | S12: SMC_IND_012 | T12: =#REF!&#REF! -> #REF! | U12: SMC_IND_012 | V12: # of surveys | X12: November | AC12: 265 | AD12: Deir al Balah | AE12: Al Birkeh | AF12: 2651099 | AJ12: Provision of site management services including strengthened coordination mechanisms, regular site monitoring, service mapping, and robust referral systems to address gaps and avoid duplication. | AK12: Protection mainstreaming | AM12: Training provided to SMA, CBO, and other stakeholders | AO12: Protection mainstreaming | AP12: Sites with safety audits conducted | AR12: Protection mainstreaming | AS12: Sites with safety audits conducted | AT12: SMC_IND_011 | AU12: # of sites
B13: PHC | D13: PHC | F13: Undertake intentions and perceptions surveys | I13: Service coordination supported and improved | J13: Number of site-level coordination meetings | L13: Service coordination supported and improved | M13: Number of site-level coordination meetings | N13: SMC_IND_014 | O13: # of meetings | S13: SMC_IND_013 | T13: =L12&M12 -> Service coordination supported and improvedNumber of service/infrastructure mapping reports generated | U13: SMC_IND_013 | V13: # of reports | X13: December | AC13: 265 | AD13: Deir al Balah | AE13: Al Bruk | AF13: 2651090 | AJ13: Provision of site management services including strengthened coordination mechanisms, regular site monitoring, service mapping, and robust referral systems to address gaps and avoid duplication. | AK13: Service coordination supported and improved | AM13: Undertake intentions and perceptions surveys | AO13: Service coordination supported and improved | AP13: Number of monitoring surveys conducted with site focal points | AR13: Service coordination supported and improved | AS13: Number of monitoring surveys conducted with site focal points | AT13: SMC_IND_012 | AU13: # of surveys
B14: UNDP | D14: UNDP | I14: Service coordination supported and improved | J14: People in sites managed or supported by trained Site Management teams | L14: Service coordination supported and improved | M14: People in sites managed or supported by trained Site Management teams | N14: SMC_IND_015 | O14: # of individuals | S14: SMC_IND_014 | T14: =L13&M13 -> Service coordination supported and improvedNumber of site-level coordination meetings | U14: SMC_IND_014 | V14: # of meetings | AC14: 265 | AD14: Deir al Balah | AE14: Al Bureij | AF14: 26503148 | AJ14: Provision of site management services including strengthened coordination mechanisms, regular site monitoring, service mapping, and robust referral systems to address gaps and avoid duplication. | AK14: Service coordination supported and improved | AO14: Service coordination supported and improved | AP14: Number of service/infrastructure mapping reports generated | AR14: Service coordination supported and improved | AS14: Number of service/infrastructure mapping reports generated | AT14: SMC_IND_013 | AU14: # of reports
B15: UNRWA | D15: UNRWA | I15: Site maintenance, risk reduction and improvements | J15: Communal spaces established or improved in sites (including safe spaces, child-friendly spaces, committee spaces, community resource spaces) | L15: Site maintenance, risk reduction and improvements | M15: Communal spaces established or improved in sites (including safe spaces, child-friendly spaces, committee spaces, community resource spaces) | N15: SMC_IND_016 | O15: # of spaces | S15: SMC_IND_015 | T15: =L14&M14 -> Service coordination supported and improvedPeople in sites managed or supported by trained Site Management teams | U15: SMC_IND_015 | V15: # of individuals | AC15: 265 | AD15: Deir al Balah | AE15: Al Bureij (east) | AF15: 26503149 | AJ15: Provision of site management services including strengthened coordination mechanisms, regular site monitoring, service mapping, and robust referral systems to address gaps and avoid duplication. | AK15: Service coordination supported and improved | AO15: Service coordination supported and improved | AP15: Number of site-level coordination meetings | AR15: Service coordination supported and improved | AS15: Number of site-level coordination meetings | AT15: SMC_IND_014 | AU15: # of meetings
I16: Site maintenance, risk reduction and improvements | J16: Number of individuals trained / supported to conduct site care and maintenance | L16: Site maintenance, risk reduction and improvements | M16: Number of individuals trained / supported to conduct site care and maintenance | N16: SMC_IND_017 | O16: # of individuals | S16: SMC_IND_016 | T16: =L15&M15 -> Site maintenance, risk reduction and improvementsCommunal spaces established or improved in sites (including safe spaces, child-friendly spaces, committee spaces, community resource spaces) | U16: SMC_IND_016 | V16: # of spaces | AC16: 265 | AD16: Deir al Balah | AE16: Al Bureij Camp | AF16: 26504182 | AJ16: Provision of site management services including strengthened coordination mechanisms, regular site monitoring, service mapping, and robust referral systems to address gaps and avoid duplication. | AK16: Service coordination supported and improved | AO16: Service coordination supported and improved | AP16: People in sites managed or supported by trained Site Management teams | AR16: Service coordination supported and improved | AS16: People in sites managed or supported by trained Site Management teams | AT16: SMC_IND_015 | AU16: # of individuals
I17: Site maintenance, risk reduction and improvements | J17: Number of sand/flour bags distributed | L17: Site maintenance, risk reduction and improvements | M17: Number of sand/flour bags distributed | N17: SMC_IND_018 | O17: # of bags | S17: SMC_IND_017 | T17: =L16&M16 -> Site maintenance, risk reduction and improvementsNumber of individuals trained / supported to conduct site care and maintenance | U17: SMC_IND_017 | V17: # of individuals | AC17: 265 | AD17: Deir al Balah | AE17: Al Farouq | AF17: 2650581 | AJ17: Works to increase safety and improve dignity of site environments, with risk mitigation measures in place to respond to incidents including seasonal impacts. | AK17: Site maintenance, risk reduction and improvements | AO17: Site maintenance, risk reduction and improvements | AP17: Communal spaces established or improved in sites (including safe spaces, child-friendly spaces, committee spaces, community resource spaces) | AR17: Site maintenance, risk reduction and improvements | AS17: Communal spaces established or improved in sites (including safe spaces, child-friendly spaces, committee spaces, community resource spaces) | AT17: SMC_IND_016 | AU17: # of spaces
I18: Site maintenance, risk reduction and improvements | J18: Number of tools distributed for site improvement (count individual tools, not toolkits) | L18: Site maintenance, risk reduction and improvements | M18: Number of tools distributed for site improvement (count individual tools, not toolkits) | N18: SMC_IND_019 | O18: # of tools | S18: SMC_IND_018 | T18: =L17&M17 -> Site maintenance, risk reduction and improvementsNumber of sand/flour bags distributed | U18: SMC_IND_018 | V18: # of bags | AC18: 265 | AD18: Deir al Balah | AE18: Al Hikr | AF18: 2651093 | AJ18: Works to increase safety and improve dignity of site environments, with risk mitigation measures in place to respond to incidents including seasonal impacts. | AK18: Site maintenance, risk reduction and improvements | AO18: Site maintenance, risk reduction and improvements | AP18: Number of individuals trained / supported to conduct site care and maintenance | AR18: Site maintenance, risk reduction and improvements | AS18: Number of individuals trained / supported to conduct site care and maintenance | AT18: SMC_IND_017 | AU18: # of individuals
I19: Site maintenance, risk reduction and improvements | J19: People in displacement sites with improvements made in site planning, facilities and/or infrastructure including (construction/repair/cleaning drainage, slope stabilisation, etc.) either directly or through community led projects | L19: Site maintenance, risk reduction and improvements | M19: People in displacement sites with improvements made in site planning, facilities and/or infrastructure including (construction/repair/cleaning drainage, slope stabilisation, etc.) either directly or through community led projects | N19: SMC_IND_020 | O19: # of individuals | S19: SMC_IND_019 | T19: =L18&M18 -> Site maintenance, risk reduction and improvementsNumber of tools distributed for site improvement (count individual tools, not toolkits) | U19: SMC_IND_019 | V19: # of tools | AC19: 265 | AD19: Deir al Balah | AE19: Al Maghazi | AF19: 26506150 | AJ19: Works to increase safety and improve dignity of site environments, with risk mitigation measures in place to respond to incidents including seasonal impacts. | AK19: Site maintenance, risk reduction and improvements | AO19: Site maintenance, risk reduction and improvements | AP19: Number of sand/flour bags distributed | AR19: Site maintenance, risk reduction and improvements | AS19: Number of sand/flour bags distributed | AT19: SMC_IND_018 | AU19: # of bags
I20: Site maintenance, risk reduction and improvements | J20: People in sites hired via Cash for Work for site maintenance/improvement | L20: Site maintenance, risk reduction and improvements | M20: People in sites hired via Cash for Work for site maintenance/improvement | N20: SMC_IND_021 | O20: # of individuals | S20: SMC_IND_020 | T20: =L19&M19 -> Site maintenance, risk reduction and improvementsPeople in displacement sites with improvements made in site planning, facilities and/or infrastructure including (construction/repair/cleaning drainage, slope stabilisation, etc.) either directly or through community led projects | U20: SMC_IND_020 | V20: # of individuals | AC20: 265 | AD20: Deir al Balah | AE20: Al Maghazi Camp | AF20: 26507184 | AJ20: Works to increase safety and improve dignity of site environments, with risk mitigation measures in place to respond to incidents including seasonal impacts. | AK20: Site maintenance, risk reduction and improvements | AO20: Site maintenance, risk reduction and improvements | AP20: Number of tools distributed for site improvement (count individual tools, not toolkits) | AR20: Site maintenance, risk reduction and improvements | AS20: Number of tools distributed for site improvement (count individual tools, not toolkits) | AT20: SMC_IND_019 | AU20: # of tools
I21: Support safe transition of site based populations | J21: Individuals supported by Site Management projects facilitating transition through access to services. Including area based site management, hubs, and community resource centres. | L21: Support safe transition of site based populations | M21: Individuals supported by Site Management projects facilitating transition through access to services. Including area based site management, hubs, and community resource centres. | N21: SMC_IND_022 | O21: # of individuals | S21: SMC_IND_021 | T21: =L20&M20 -> Site maintenance, risk reduction and improvementsPeople in sites hired via Cash for Work for site maintenance/improvement | U21: SMC_IND_021 | V21: # of individuals | AC21: 265 | AD21: Deir al Balah | AE21: Al-Louh | AF21: 2651037 | AJ21: Works to increase safety and improve dignity of site environments, with risk mitigation measures in place to respond to incidents including seasonal impacts. | AK21: Site maintenance, risk reduction and improvements | AO21: Site maintenance, risk reduction and improvements | AP21: People in displacement sites with improvements made in site planning, facilities and/or infrastructure including (construction/repair/cleaning drainage, slope stabilisation, etc.) either directly or through community led projects | AR21: Site maintenance, risk reduction and improvements | AS21: People in displacement sites with improvements made in site planning, facilities and/or infrastructure including (construction/repair/cleaning drainage, slope stabilisation, etc.) either directly or through community led projects | AT21: SMC_IND_020 | AU21: # of individuals
I22: Support safe transition of site based populations | J22: Site Management projects facilitating transition through access to services. Including area based site management, hubs, and community resource centres. | L22: Support safe transition of site based populations | M22: Site Management projects facilitating transition through access to services. Including area based site management, hubs, and community resource centres. | N22: SMC_IND_023 | O22: # of projects | S22: SMC_IND_022 | T22: =L21&M21 -> Support safe transition of site based populationsIndividuals supported by Site Management projects facilitating transition through access to services. Including area based site management, hubs, and community resource centres. | U22: SMC_IND_022 | V22: # of individuals | AC22: 265 | AD22: Deir al Balah | AE22: AL-Shortah | AF22: 2651142 | AJ22: Works to increase safety and improve dignity of site environments, with risk mitigation measures in place to respond to incidents including seasonal impacts. | AK22: Site maintenance, risk reduction and improvements | AO22: Site maintenance, risk reduction and improvements | AP22: People in sites hired via Cash for Work for site maintenance/improvement | AR22: Site maintenance, risk reduction and improvements | AS22: People in sites hired via Cash for Work for site maintenance/improvement | AT22: SMC_IND_021 | AU22: # of individuals
I23: Training provided to community representation structures | J23: Number of individuals who have recieved training in community representation structures | L23: Training provided to community representation structures | M23: Number of individuals who have recieved training in community representation structures | N23: SMC_IND_024 | O23: # of participants | S23: SMC_IND_023 | T23: =L22&M22 -> Support safe transition of site based populationsSite Management projects facilitating transition through access to services. Including area based site management, hubs, and community resource centres. | U23: SMC_IND_023 | V23: # of projects | AC23: 265 | AD23: Deir al Balah | AE23: An Nuseirat | AF23: 26501147 | AJ23: Support to populations to transition out of sites including support to populations out of sites, community engagement, support for relocation and safe site closures. | AK23: Support safe transition of site based populations | AO23: Support safe transition of site based populations | AP23: Individuals supported by Site Management projects facilitating transition through access to services. Including area based site management, hubs, and community resource centres. | AR23: Support safe transition of site based populations | AS23: Individuals supported by Site Management projects facilitating transition through access to services. Including area based site management, hubs, and community resource centres. | AT23: SMC_IND_022 | AU23: # of individuals
I24: Training provided to community representation structures | J24: Trainings provided to community representation structures | L24: Training provided to community representation structures | M24: Trainings provided to community representation structures | N24: SMC_IND_025 | O24: # of trainings | S24: SMC_IND_024 | T24: =L23&M23 -> Training provided to community representation structuresNumber of individuals who have recieved training in community representation structures | U24: SMC_IND_024 | V24: # of participants | AC24: 265 | AD24: Deir al Balah | AE24: An Nuseirat Camp | AF24: 26502183 | AJ24: Support to populations to transition out of sites including support to populations out of sites, community engagement, support for relocation and safe site closures. | AK24: Support safe transition of site based populations | AO24: Support safe transition of site based populations | AP24: Site Management projects facilitating transition through access to services. Including area based site management, hubs, and community resource centres. | AR24: Support safe transition of site based populations | AS24: Site Management projects facilitating transition through access to services. Including area based site management, hubs, and community resource centres. | AT24: SMC_IND_023 | AU24: # of projects
I25: Training provided to SMA, CBO, and other stakeholders | J25: Individuals received training in Site Management, including SMA and CBO staff and volunteers, and other stakeholders. | L25: Training provided to SMA, CBO, and other stakeholders | M25: Individuals received training in Site Management, including SMA and CBO staff and volunteers, and other stakeholders. | N25: SMC_IND_026 | O25: # of individuals | S25: SMC_IND_025 | T25: =L24&M24 -> Training provided to community representation structuresTrainings provided to community representation structures | U25: SMC_IND_025 | V25: # of trainings | AC25: 265 | AD25: Deir al Balah | AE25: Ansar | AF25: 2650582 | AJ25: Establishment and strengthening of community representation structures, with two way communication mechanisms in place | AK25: Training provided to community representation structures | AO25: Training provided to community representation structures | AP25: Number of individuals who have recieved training in community representation structures | AR25: Training provided to community representation structures | AS25: Number of individuals who have recieved training in community representation structures | AT25: SMC_IND_024 | AU25: # of participants
I26: Undertake intentions and perceptions surveys | J26: Intentions or perceptions surveys conducted | L26: Undertake intentions and perceptions surveys | M26: Intentions or perceptions surveys conducted | N26: SMC_IND_027 | O26: # of assessments | S26: SMC_IND_026 | T26: =L25&M25 -> Training provided to SMA, CBO, and other stakeholdersIndividuals received training in Site Management, including SMA and CBO staff and volunteers, and other stakeholders. | U26: SMC_IND_026 | V26: # of individuals | AC26: 265 | AD26: Deir al Balah | AE26: Ar Rahmeh | AF26: 2650596 | AJ26: Establishment and strengthening of community representation structures, with two way communication mechanisms in place | AK26: Training provided to community representation structures | AO26: Training provided to community representation structures | AP26: Trainings provided to community representation structures | AR26: Training provided to community representation structures | AS26: Trainings provided to community representation structures | AT26: SMC_IND_025 | AU26: # of trainings
S27: SMC_IND_027 | T27: =L26&M26 -> Undertake intentions and perceptions surveysIntentions or perceptions surveys conducted | U27: SMC_IND_027 | V27: # of assessments | AC27: 265 | AD27: Deir al Balah | AE27: Ar Rasheed | AF27: 2650575 | AJ27: Capacity-strengthening for SMA staff and voluntunteers, CBOs, other sectoral agencies and stakeholders | AK27: Training provided to SMA, CBO, and other stakeholders | AO27: Training provided to SMA, CBO, and other stakeholders | AP27: Individuals received training in Site Management, including SMA and CBO staff and volunteers, and other stakeholders. | AR27: Training provided to SMA, CBO, and other stakeholders | AS27: Individuals received training in Site Management, including SMA and CBO staff and volunteers, and other stakeholders. | AT27: SMC_IND_026 | AU27: # of individuals
AC28: 265 | AD28: Deir al Balah | AE28: Ar Rasheed | AF28: 2650595 | AJ28: Support to populations to transition out of sites including support to populations out of sites, community engagement, support for relocation and safe site closures. | AK28: Undertake intentions and perceptions surveys | AO28: Undertake intentions and perceptions surveys | AP28: Intentions or perceptions surveys conducted | AR28: Undertake intentions and perceptions surveys | AS28: Intentions or perceptions surveys conducted | AT28: SMC_IND_027 | AU28: # of assessments
AC29: 265 | AD29: Deir al Balah | AE29: As Safa | AF29: 2650885
AC30: 265 | AD30: Deir al Balah | AE30: As Sahabah | AF30: 2650577
AC31: 265 | AD31: Deir al Balah | AE31: As Salah | AF31: 2650578
AC32: 265 | AD32: Deir al Balah | AE32: As Salam | AF32: 2651092
AC33: 265 | AD33: Deir al Balah | AE33: As Samah | AF33: 2650576
AC34: 265 | AD34: Deir al Balah | AE34: As Siddeq | AF34: 2650580
AC35: 265 | AD35: Deir al Balah | AE35: As Sidra | AF35: 2650887
AC36: 265 | AD36: Deir al Balah | AE36: Az Zawayda (north) | AF36: 26505193
AC37: 265 | AD37: Deir al Balah | AE37: Deir Al Balah (east) | AF37: 26510151
AC38: 265 | AD38: Deir al Balah | AE38: Deir Al Balah (south) | AF38: 26510152
AC39: 265 | AD39: Deir al Balah | AE39: Deir al Balah Camp | AF39: 26509185
AC40: 265 | AD40: Deir al Balah | AE40: Ja'afarawi | AF40: 2651041
...

Sheet COD-Sites
A1: Site ID | B1: Site Name | C1: Site Name (ar) | D1: Governorate | E1: Governorate_PCODE | F1: Neighborhood | G1: HelperConcat | H1: Site | I1: NeighborhoodPcode | J1: Site Agency | K1: Implementing Partner | L1: FinalImplementingPartner | M1: Site Status | N1: Agency
A2: DEB0038 | B2: D/Balah Elem. Co-ed A & B | C2: مدرسه ديرالبلح المشتركه ا . ب ( البصه ) | D2: Deir Al-Balah | E2: 265 | F2: Al Bassa | G2: Deir Al-BalahAl BassaUNRWA | H2: D/Balah Elem. Co-ed A & B | I2: 2651091 | J2: UNRWA | L2: =IF(OR(ISBLANK(tblSites[[#This Row],[Implementing Partner]]), tblSites[[#This Row],[Implementing Partner]]="-"), tblSites[[#This Row],[Site Agency]], tblSites[[#This Row],[Implementing Partner]]) -> UNRWA | M2: Active | N2: =tblSites[[#This Row],[FinalImplementingPartner]] -> UNRWA
A3: DEB0039 | B3: D/Balah Prep. Boys "A" & "B" | C3: مدرسة دير البلح الإعدادية للبنين "أ" و"ب" | D3: Deir Al-Balah | E3: 265 | F3: Deir al Balah Camp | G3: Deir Al-BalahDeir al Balah CampUNRWA | H3: D/Balah Prep. Boys "A" & "B" | I3: 26509185 | J3: UNRWA | L3: =IF(OR(ISBLANK(tblSites[[#This Row],[Implementing Partner]]), tblSites[[#This Row],[Implementing Partner]]="-"), tblSites[[#This Row],[Site Agency]], tblSites[[#This Row],[Implementing Partner]]) -> UNRWA | M3: Active | N3: =tblSites[[#This Row],[FinalImplementingPartner]] -> UNRWA
A4: DEB0040 | B4: D/Balah Prep. Girls "A" & "B" | C4: مدرسة بنات دير البلح الاعدادية أ+ب | D4: Deir Al-Balah | E4: 265 | F4: Al Bassa | G4: Deir Al-BalahAl BassaUNRWA | H4: D/Balah Prep. Girls "A" & "B" | I4: 2651091 | J4: UNRWA | L4: =IF(OR(ISBLANK(tblSites[[#This Row],[Implementing Partner]]), tblSites[[#This Row],[Implementing Partner]]="-"), tblSites[[#This Row],[Site Agency]], tblSites[[#This Row],[Implementing Partner]]) -> UNRWA | M4: Active | N4: =tblSites[[#This Row],[FinalImplementingPartner]] -> UNRWA
A5: DEB0041 | B5: D/Balah Elem. Boys A & B | C5: مدرسه ذكور ديرالبلح الابتدائيه أ .ب المعسكر | D5: Deir Al-Balah | E5: 265 | F5: Deir al Balah Camp | G5: Deir Al-BalahDeir al Balah CampUNRWA | H5: D/Balah Elem. Boys A & B | I5: 26509185 | J5: UNRWA | L5: =IF(OR(ISBLANK(tblSites[[#This Row],[Implementing Partner]]), tblSites[[#This Row],[Implementing Partner]]="-"), tblSites[[#This Row],[Site Agency]], tblSites[[#This Row],[Implementing Partner]]) -> UNRWA | M5: Active | N5: =tblSites[[#This Row],[FinalImplementingPartner]] -> UNRWA
A6: DEB0042 | B6: D/Balah Prep. Boys "C" | C6: مركز ايواء ذكور دير البلح الاعدادية -ج- | D6: Deir Al-Balah | E6: 265 | F6: Al Hikr | G6: Deir Al-BalahAl HikrUNRWA | H6: D/Balah Prep. Boys "C" | I6: 2651093 | J6: UNRWA | L6: =IF(OR(ISBLANK(tblSites[[#This Row],[Implementing Partner]]), tblSites[[#This Row],[Implementing Partner]]="-"), tblSites[[#This Row],[Site Agency]], tblSites[[#This Row],[Implementing Partner]]) -> UNRWA | M6: Active | N6: =tblSites[[#This Row],[FinalImplementingPartner]] -> UNRWA
A7: DEB0046 | B7: Nuseirat Prep. Co-ed "A" | C7: مدرسة النصيرات الإعدادية المشتركة أ | D7: Deir Al-Balah | E7: 265 | F7: An Nuseirat | G7: Deir Al-BalahAn NuseiratUNRWA | H7: Nuseirat Prep. Co-ed "A" | I7: 26501147 | J7: UNRWA | L7: =IF(OR(ISBLANK(tblSites[[#This Row],[Implementing Partner]]), tblSites[[#This Row],[Implementing Partner]]="-"), tblSites[[#This Row],[Site Agency]], tblSites[[#This Row],[Implementing Partner]]) -> UNRWA | M7: Active | N7: =tblSites[[#This Row],[FinalImplementingPartner]] -> UNRWA
A8: DEB0047 | B8: Nuseirat Elem. Co-ed "G" & Prep.Girls "C" | D8: Deir Al-Balah | E8: 265 | F8: An Nuseirat | G8: Deir Al-BalahAn NuseiratUNRWA | H8: Nuseirat Elem. Co-ed "G" & Prep.Girls "C" | I8: 26501147 | J8: UNRWA | L8: =IF(OR(ISBLANK(tblSites[[#This Row],[Implementing Partner]]), tblSites[[#This Row],[Implementing Partner]]="-"), tblSites[[#This Row],[Site Agency]], tblSites[[#This Row],[Implementing Partner]]) -> UNRWA | M8: Active | N8: =tblSites[[#This Row],[FinalImplementingPartner]] -> UNRWA
A9: DEB0051 | B9: New Nuseirat Elem. Coed & Nuseirat Prep. Girls "A" - Official AOR | D9: Deir Al-Balah | E9: 265 | F9: An Nuseirat Camp | G9: Deir Al-BalahAn Nuseirat CampUNRWA | H9: New Nuseirat Elem. Coed & Nuseirat Prep. Girls "A" - Official AOR | I9: 26502183 | J9: UNRWA | L9: =IF(OR(ISBLANK(tblSites[[#This Row],[Implementing Partner]]), tblSites[[#This Row],[Implementing Partner]]="-"), tblSites[[#This Row],[Site Agency]], tblSites[[#This Row],[Implementing Partner]]) -> UNRWA | M9: Active | N9: =tblSites[[#This Row],[FinalImplementingPartner]] -> UNRWA
A10: DEB0052 | B10: Nuseirat Elem. Co-ed "F" & "A" | C10: مركز إيواء مدرسة النصيرات الابتدائية المشتركة أ ،و | D10: Deir Al-Balah | E10: 265 | F10: An Nuseirat Camp | G10: Deir Al-BalahAn Nuseirat CampUNRWA | H10: Nuseirat Elem. Co-ed "F" & "A" | I10: 26502183 | J10: UNRWA | L10: =IF(OR(ISBLANK(tblSites[[#This Row],[Implementing Partner]]), tblSites[[#This Row],[Implementing Partner]]="-"), tblSites[[#This Row],[Site Agency]], tblSites[[#This Row],[Implementing Partner]]) -> UNRWA | M10: Active | N10: =tblSites[[#This Row],[FinalImplementingPartner]] -> UNRWA
A11: DEB0053 | B11: Nuseirat Prep. Boys "A" & Elem. Boys "A" | C11: مركزايواءذكورالنصيرات-الاعداديةأ | D11: Deir Al-Balah | E11: 265 | F11: Al Farouq | G11: Deir Al-BalahAl FarouqUNRWA | H11: Nuseirat Prep. Boys "A" & Elem. Boys "A" | I11: 2650581 | J11: UNRWA | L11: =IF(OR(ISBLANK(tblSites[[#This Row],[Implementing Partner]]), tblSites[[#This Row],[Implementing Partner]]="-"), tblSites[[#This Row],[Site Agency]], tblSites[[#This Row],[Implementing Partner]]) -> UNRWA | M11: Active | N11: =tblSites[[#This Row],[FinalImplementingPartner]] -> UNRWA
A12: DEB0054 | B12: Nuseirat Prep. Boys "D" & Elem. Boys "C" | D12: Deir Al-Balah | E12: 265 | F12: An Nuseirat Camp | G12: Deir Al-BalahAn Nuseirat CampUNRWA | H12: Nuseirat Prep. Boys "D" & Elem. Boys "C" | I12: 26502183 | J12: UNRWA | L12: =IF(OR(ISBLANK(tblSites[[#This Row],[Implementing Partner]]), tblSites[[#This Row],[Implementing Partner]]="-"), tblSites[[#This Row],[Site Agency]], tblSites[[#This Row],[Implementing Partner]]) -> UNRWA | M12: Active | N12: =tblSites[[#This Row],[FinalImplementingPartner]] -> UNRWA
A13: DEB0055 | B13: Nusierat Prep. Girls D & F | D13: Deir Al-Balah | E13: 265 | F13: An Nuseirat | G13: Deir Al-BalahAn NuseiratUNRWA | H13: Nusierat Prep. Girls D & F | I13: 26501147 | J13: UNRWA | L13: =IF(OR(ISBLANK(tblSites[[#This Row],[Implementing Partner]]), tblSites[[#This Row],[Implementing Partner]]="-"), tblSites[[#This Row],[Site Agency]], tblSites[[#This Row],[Implementing Partner]]) -> UNRWA | M13: Active | N13: =tblSites[[#This Row],[FinalImplementingPartner]] -> UNRWA
A14: DEB0056 | B14: Nuseirat Elem. Boys "B" & Girls "A" | D14: Deir Al-Balah | E14: 265 | F14: An Nuseirat Camp | G14: Deir Al-BalahAn Nuseirat CampUNRWA | H14: Nuseirat Elem. Boys "B" & Girls "A" | I14: 26502183 | J14: UNRWA | L14: =IF(OR(ISBLANK(tblSites[[#This Row],[Implementing Partner]]), tblSites[[#This Row],[Implementing Partner]]="-"), tblSites[[#This Row],[Site Agency]], tblSites[[#This Row],[Implementing Partner]]) -> UNRWA | M14: Active | N14: =tblSites[[#This Row],[FinalImplementingPartner]] -> UNRWA
A15: DEB0058 | B15: Nuseirat Prep. Girls "B" | D15: Deir Al-Balah | E15: 265 | F15: An Nuseirat Camp | G15: Deir Al-BalahAn Nuseirat CampUNRWA | H15: Nuseirat Prep. Girls "B" | I15: 26502183 | J15: UNRWA | L15: =IF(OR(ISBLANK(tblSites[[#This Row],[Implementing Partner]]), tblSites[[#This Row],[Implementing Partner]]="-"), tblSites[[#This Row],[Site Agency]], tblSites[[#This Row],[Implementing Partner]]) -> UNRWA | M15: Active | N15: =tblSites[[#This Row],[FinalImplementingPartner]] -> UNRWA
